// Utility function to catch async errors
const catchAsync = (fn) => {
  return (req, res, next) => {
    fn(req, res, next).catch(next);
  };
};

module.exports = catchAsync; 